Traceback (most recent call last):
  File "/Users/Ziad/miniforge3/lib/python3.9/site-packages/jupyter_cache/executors/utils.py", line 58, in single_nb_execution
    executenb(
  File "/Users/Ziad/miniforge3/lib/python3.9/site-packages/nbclient/client.py", line 1305, in execute
    return NotebookClient(nb=nb, resources=resources, km=km, **kwargs).execute()
  File "/Users/Ziad/miniforge3/lib/python3.9/site-packages/jupyter_core/utils/__init__.py", line 166, in wrapped
    return loop.run_until_complete(inner)
  File "/Users/Ziad/miniforge3/lib/python3.9/asyncio/base_events.py", line 642, in run_until_complete
    return future.result()
  File "/Users/Ziad/miniforge3/lib/python3.9/site-packages/nbclient/client.py", line 705, in async_execute
    await self.async_execute_cell(
  File "/Users/Ziad/miniforge3/lib/python3.9/site-packages/nbclient/client.py", line 1058, in async_execute_cell
    await self._check_raise_for_error(cell, cell_index, exec_reply)
  File "/Users/Ziad/miniforge3/lib/python3.9/site-packages/nbclient/client.py", line 914, in _check_raise_for_error
    raise CellExecutionError.from_cell_and_msg(cell, exec_reply_content)
nbclient.exceptions.CellExecutionError: An error occurred while executing the following cell:
------------------
ziad_car.drive(miles_driven)
print("Ziad's Car's Gas: ", ziad_car.gas)
------------------


[0;31m---------------------------------------------------------------------------[0m
[0;31mAttributeError[0m                            Traceback (most recent call last)
Cell [0;32mIn[13], line 1[0m
[0;32m----> 1[0m [43mziad_car[49m[38;5;241;43m.[39;49m[43mdrive[49m(miles_driven)
[1;32m      2[0m [38;5;28mprint[39m([38;5;124m"[39m[38;5;124mZiad[39m[38;5;124m'[39m[38;5;124ms Car[39m[38;5;124m'[39m[38;5;124ms Gas: [39m[38;5;124m"[39m, ziad_car[38;5;241m.[39mgas)

[0;31mAttributeError[0m: 'Car' object has no attribute 'drive'

